Workbook

Sheet Resumo
A1: Aspectos gerais | D1: Status
A2: ID# | B2: Área | C2: Aspecto verificado | D2: 46131 | E2: 46138 | F2: 46140
A51: Testes
A52: Tipo | B52: ID | C52: Descrição

Sheet Check_T1T2
A1: Resultados das verificações
A2: Fase da arquitectura inicial
A3: T1 e T2 - 2 de Março a 5 de Abril
A5: Aspecto | B5: Estado | C5: Resultado
A6: Variante MVC adoptada | B6: Verificado | C6: Conforme: arranque no Controller, input na View, coordenação pelo Controller, processamento no Model, retorno à View, sem fluxo directo Model -> Controller.
A7: Inputs e outputs principais | B7: Verificado | C7: Conforme: consultar stock, introduzir dados, remover quantidade, gerar lista e sair; outputs de menu, stock, confirmação, sucesso, erro, lista e fecho.
A8: Diagrama de sequência | B8: Verificado | C8: Conforme: cobre arranque, consulta, adicionar/actualizar, remover, caso alternativo de stock insuficiente, lista de reposição e encerramento.
A9: Estrutura arquitectónica | B9: Verificado | C9: Conforme: responsabilidades de View, Controller e Model estão claras; persistência JSON integrada no Model.
A10: Coerência entre artefactos | B10: Verificado | C10: Conforme: relatório, diagrama de comunicação e diagrama de sequência estão alinhados nos pontos essenciais.
A11: Evolução completa entre versões | B11: Parcialmente verificado | C11: Foi possível verificar bem a versão final, mas não reconstruir todo o percurso intermédio entre versões com detalhe total.

Sheet CheckT3_20260419
A1: ID# | B1: Área | C1: Aspecto verificado | D1: Ficheiro/Local | E1: Critério | F1: Estado | G1: Evidência | H1: Problema detectado | I1: Correcção sugerida | J1: Prioridade | K1: Data
A2: 1 | B2: MVC | C2: Arranque da aplicação | D2: Program.cs | E2: Program apenas arranca o Controller | F2: Conforme | G2: Controller controller = new Controller(); controller.IniciarPrograma(); | J2: Baixa | K2: 46131 | L2: =B2&C2&D2&E2
A3: 2 | B3: MVC | C3: Arranque no Controller | D3: Controller.cs | E3: O ciclo da aplicação deve iniciar no Controller e passar para a View | F3: Conforme | G3: IniciarPrograma() chama view.MostrarMenu(); | J3: Baixa | K3: 46131 | L3: =B3&C3&D3&E3
A4: 3 | B4: MVC | C4: Controller como ponto central de ligação | D4: Controller.cs | E4: O Controller deve instanciar e ligar View e Model | F4: Conforme | G4: Instancia view e model, carrega dados e faz todas as subscrições no construtor | J4: Baixa | K4: 46131 | L4: =B4&C4&D4&E4
A5: 4 | B5: MVC | C5: Input entra na View | D5: View.cs | E5: A variante Curry & Grace exige input na View | F5: Conforme | G5: MostrarMenu, PedirDadosProduto e PedirRemocaoQuantidade recolhem o input do utilizador | J5: Baixa | K5: 46131 | L5: =B5&C5&D5&E5
A6: 5 | B6: MVC | C6: View não conhece directamente o Model | D6: View.cs | E6: A View não deve instanciar nem referenciar directamente o Model | F6: Conforme | G6: View.cs não instancia nem usa a classe Model; apenas expõe eventos/delegados | J6: Baixa | K6: 46131 | L6: =B6&C6&D6&E6
A7: 6 | B7: MVC | C7: Model não conhece View nem Controller | D7: Model.cs | E7: O Model não deve depender de View nem Controller | F7: Conforme | G7: Model.cs não referencia View nem Controller | J7: Baixa | K7: 46131 | L7: =B7&C7&D7&E7
A8: 7 | B8: MVC | C8: Saída apresentada pela View | D8: View.cs | E8: Os resultados devem ser apresentados na View | F8: Conforme | G8: MostrarStock, MostrarListaReposicao, MostrarConfirmacao, MostrarErro, MostrarMensagemFinal | J8: Baixa | K8: 46131 | L8: =B8&C8&D8&E8
A9: 8 | B9: MVC | C9: Papel do Controller limitado à coordenação | D9: Controller.cs | E9: O Controller não deve conter lógica de negócio do domínio | F9: Conforme | G9: Faz encaminhamento, validação básica e coordenação; não implementa regras de stock nem persistência | J9: Baixa | K9: 46131 | L9: =B9&C9&D9&E9
A10: 9 | B10: Eventos/Delegados | C10: Input da View chega ao Controller por eventos | D10: Controller.cs | E10: Os inputs do utilizador devem ser recebidos pelo Controller via eventos | F10: Conforme | G10: view.OpcaoSelecionada += ProcessarOpcao;, view.DadosProdutoIntroduzidos += RegistarOuAtualizarProduto;, view.RemocaoSolicitada += RemoverQuantidade; | J10: Baixa | K10: 46131 | L10: =B10&C10&D10&E10
A11: 10 | B11: Eventos/Delegados | C11: Pedidos de consulta e reposição estão ligados por delegados | D11: Controller.cs / View.cs | E11: Os pedidos de leitura devem estar formalmente ligados no arranque | F11: Conforme | G11: view.PrecisoDeProdutos += model.SolicitarListaProdutos; e view.PrecisoDeListaReposicao += model.SolicitarListaReposicao; | H11: Este encadeamento contribui para o desvio face ao diagrama V5 nos fluxos de consulta e reposição | I11: Clarificar documentalmente este fluxo ou passar também estes pedidos por handlers explícitos no Controller | J11: Média | K11: 46131 | L11: =B11&C11&D11&E11
A12: 11 | B12: Eventos/Delegados | C12: Notificações do Model chegam à View por eventos | D12: Controller.cs | E12: As respostas do Model devem chegar à View por eventos | F12: Conforme | G12: model.OperacaoConcluida += view.MostrarConfirmacao;, model.ErroStockInsuficiente += view.MostrarErro; | J12: Baixa | K12: 46131 | L12: =B12&C12&D12&E12
A13: 12 | B13: Eventos/Delegados | C13: Invocação segura de eventos na View | D13: View.cs | E13: A View deve invocar eventos com verificação nula | F13: Conforme | G13: Uso de ?.Invoke(...) nos eventos de input | J13: Baixa | K13: 46131 | L13: =B13&C13&D13&E13
A14: 13 | B14: Acoplamento | C14: Ausência de acoplamento estrutural View -> Model | D14: View.cs | E14: A View não deve criar nem conhecer o Model | F14: Conforme | G14: A View apenas expõe contratos de comunicação; não conhece a implementação do Model | J14: Baixa | K14: 46131 | L14: =B14&C14&D14&E14
A15: 14 | B15: Acoplamento | C15: Ausência de acoplamento estrutural Model -> View/Controller | D15: Model.cs | E15: O Model deve estar isolado dos outros componentes | F15: Conforme | G15: O Model apenas expõe eventos e métodos próprios | J15: Baixa | K15: 46131 | L15: =B15&C15&D15&E15
A16: 15 | B16: Acoplamento | C16: Mediação explícita do Controller nos fluxos de leitura | D16: Controller.cs / arquitectura | E16: Os fluxos principais devem passar explicitamente pelo Controller | F16: Parcial | G16: Em consulta e reposição, a View acciona delegados ligados ao Model | H16: O fluxo real fica menos explícito do que no diagrama V5 | I16: Ou ajustar a documentação, ou fazer também estes pedidos passar por handlers próprios no Controller | J16: Alta | K16: 46131 | L16: =B16&C16&D16&E16
A17: 16 | B17: Documentação | C17: Coerência com a variante Curry & Grace adoptada | D17: Código + decisão da equipa | E17: O código deve manter input na View e coordenação geral no Controller | F17: Conforme | G17: O padrão geral do código respeita a decisão arquitectónica assumida | J17: Baixa | K17: 46131 | L17: =B17&C17&D17&E17
A18: 17 | B18: Documentação | C18: Coerência entre código e diagrama de sequência V5 | D18: Controller.cs / View.cs / diagrama V5 | E18: O fluxo implementado deve coincidir com o fluxo documentado | F18: Não conforme | G18: No diagrama, consulta/reposição seguem View -> Controller -> Model; no código, a View acciona delegados ligados ao Model | H18: Desvio real entre implementação e documentação | I18: Harmonizar diagrama/documentação com o código, ou refactorizar o código | J18: Alta | K18: 46131 | L18: =B18&C18&D18&E18
A19: 18 | B19: Implementação | C19: Estrutura base do Controller implementada | D19: Controller.cs | E19: O Controller deve estar funcional ao nível do arranque, coordenação e encerramento | F19: Conforme | G19: Construtor, handlers, IniciarPrograma() e Encerrar() estão implementados | H19: Encerrar() usa Environment.Exit(0), o que dificulta a execução de testes automáticos e de integração no próprio projecto | I19: Substituir por mecanismo de fecho controlado quando se avançar para a fase de testes | J19: Média | K19: 46131 | L19: =B19&C19&D19&E19
A20: 19 | B20: Implementação | C20: Ciclo do menu sem recursão acumulada | D20: Controller.cs / View.cs | E20: O fluxo principal não deve acumular chamadas recursivas ao menu | F20: Não conforme | G20: MostrarMenu() acciona OpcaoSelecionada; ProcessarOpcao() termina com nova chamada a view.MostrarMenu() | H20: O ciclo actual é recursivo e pode acumular chamadas em profundidade | I20: Reestruturar o ciclo principal com controlo iterativo em vez de recursivo | J20: Alta | K20: 46131 | L20: =B20&C20&D20&E20
A21: 20 | B21: Implementação | C21: Menu não duplicado em casos de erro de validação | D21: Controller.cs | E21: Em caso de erro de validação, o menu não deve ser reapresentado duas vezes | F21: Não conforme | G21: Em RegistarOuAtualizarProduto() e RemoverQuantidade(), quando os dados são inválidos, é chamado view.MostrarMenu(); depois ProcessarOpcao() volta a chamar view.MostrarMenu() | H21: Reapresentação duplicada do menu em cenários de erro | I21: Centralizar a decisão de regressar ao menu num único ponto do fluxo | J21: Média | K21: 46131 | L21: =B21&C21&D21&E21
A22: 21 | B22: Implementação | C22: Estrutura base da View implementada | D22: View.cs | E22: A View deve suportar menu, recolha de input e apresentação de output | F22: Conforme | G22: Métodos principais da interface de consola estão implementados | J22: Baixa | K22: 46131 | L22: =B22&C22&D22&E22
A23: 22 | B23: Implementação | C23: Leitura válida de inteiros na View | D23: View.cs | E23: A View deve validar input numérico básico | F23: Conforme | G23: LerInteiro() implementado com repetição até valor válido | J23: Baixa | K23: 46131 | L23: =B23&C23&D23&E23
A24: 23 | B24: Implementação | C24: Classe de dados Produto definida | D24: Produto.cs | E24: Deve existir uma estrutura de dados para o domínio | F24: Conforme | G24: Classe com Nome, Quantidade, QuantidadeMinima e Unidade | J24: Baixa | K24: 46131 | L24: =B24&C24&D24&E24
A25: 24 | B25: Implementação | C25: Métodos de consulta do Model implementados | D25: Model.cs | E25: SolicitarListaProdutos e SolicitarListaReposicao devem estar funcionais | F25: Não conforme | G25: Ambos os métodos estão com TODO | H25: Fluxos de leitura ainda não implementados | I25: Implementar cópia segura da lista e filtragem de reposição | J25: Alta | K25: 46131 | L25: =B25&C25&D25&E25
A26: 25 | B26: Implementação | C26: Métodos de lógica de negócio do Model implementados | D26: Model.cs | E26: RegistarOuAtualizarProduto e RemoverQuantidade devem estar funcionais | F26: Não conforme | G26: Ambos os métodos estão com TODO | H26: Fluxos principais da aplicação ainda não estão implementados | I26: Implementar lógica de actualização, remoção e disparo de notificações | J26: Alta | K26: 46131 | L26: =B26&C26&D26&E26
A27: 26 | B27: Implementação | C27: Persistência JSON implementada | D27: Model.cs | E27: CarregarDados e GuardarDados devem estar funcionais | F27: Não conforme | G27: Ambos os métodos estão com TODO; já são chamados pelo Controller | H27: Persistência prevista mas ainda não implementada | I27: Implementar leitura/escrita JSON | J27: Alta | K27: 46131 | L27: =B27&C27&D27&E27
A28: 27 | B28: Implementação | C28: Dependência da API JSON declarada no projecto | D28: GestorStockDomestico.csproj | E28: O projecto deve declarar a dependência necessária para Json.NET, se a persistência a usar for mesmo essa | F28: Não conforme | G28: O .csproj não tem qualquer referência a Newtonsoft.Json | H28: Falta preparação do projecto para a persistência prevista | I28: Adicionar a dependência correcta da biblioteca a utilizar | J28: Alta | K28: 46131 | L28: =B28&C28&D28&E28
A29: 28 | B29: Implementação | C29: Pasta de testes preparada | D29: tests/README.md | E29: A área de testes deve ter pelo menos estrutura mínima identificada | F29: Parcial | G29: Existe a pasta tests e um README a dizer que ali ficarão testes, casos de teste e resultados | H29: Estrutura apenas declarativa; ainda sem artefactos reais | I29: Criar projecto de testes e registo efectivo do verificador | J29: Média | K29: 46131 | L29: =B29&C29&D29&E29
A30: 29 | B30: Testes | C30: Plano de testes unitários | D30: Registo do Verificador | E30: Devem estar definidos casos de teste para Controller e Model | F30: Em preparação | G30: Já é possível identificar operações críticas do Controller e do Model | H30: A matriz ainda não está formalizada | I30: Fechar a matriz de testes unitários no Excel/ficheiro de apoio | J30: Média | K30: 46131 | L30: =B30&C30&D30&E30
A31: 30 | B31: Testes | C31: Testes unitários do Controller executados | D31: Próprio projecto | E31: Deve existir validação do encaminhamento e subscrição dos fluxos | F31: Não executado nesta fase | G31: Ainda não existem métodos/casos/resultados de teste integrados no código actual | H31: O trabalho de testes ainda não arrancou formalmente | I31: Executar após fecho mínimo dos fluxos e definição dos cenários | J31: Média | K31: 46131 | L31: =B31&C31&D31&E31
A32: 31 | B32: Testes | C32: Testes unitários do Model executados | D32: Próprio projecto | E32: Deve existir validação da lógica de negócio e persistência | F32: Não executado nesta fase | G32: Os métodos críticos do Model continuam por implementar | H32: O estado actual do Model impede testes unitários úteis | I32: Executar após implementação mínima funcional | J32: Média | K32: 46131 | L32: =B32&C32&D32&E32
A33: 32 | B33: Testes | C33: Testabilidade da View | D33: View.cs | E33: A View deve manter-se focada em input/output para não dificultar validação posterior | F33: Parcial | G33: A View está bem separada do domínio, mas depende fortemente da consola | H33: Forte componente interactiva dificulta testes automáticos directos | I33: Evitar acrescentar lógica à View e privilegiar validação indirecta/integrada | J33: Média | K33: 46131 | L33: =B33&C33&D33&E33
A34: 33 | B34: Testes | C34: Plano de testes de integração | D34: Registo do Verificador | E34: Devem estar definidos cenários View -> Controller -> Model -> View | F34: Em preparação | G34: Os cenários já podem ser identificados a partir do protótipo e do diagrama | H34: Ainda falta formalizar e calendarizar a execução | I34: Definir cenários de consulta, registo, remoção, erro, reposição e saída | J34: Média | K34: 46131 | L34: =B34&C34&D34&E34
A35: 34 | B35: Testes | C35: Testes de integração executados | D35: Próprio projecto | E35: Os fluxos principais devem ser validados ponta-a-ponta | F35: Não executado nesta fase | G35: A integração estrutural existe, mas a implementação está incompleta e há desvio com a documentação | H35: Ainda não há base estável para validação integrada formal | I35: Executar após fecho funcional mínimo e harmonização código-documentação | J35: Média | K35: 46131 | L35: =B35&C35&D35&E35
L36: =B36&C36&D36&E36

Sheet CheckT3_20260426
A1: ID# | B1: Área | C1: Aspecto verificado | D1: Ficheiro/Local | E1: Critério | F1: Estado | G1: Evidência | H1: Problema detectado | I1: Correcção sugerida | J1: Prioridade | K1: Data
A2: =_xlfn.XLOOKUP(L2,CheckT3_20260419!L:L,CheckT3_20260419!A:A) | B2: Acoplamento | C2: Mediação explícita do Controller nos fluxos de leitura | D2: Controller.cs / arquitectura | E2: Os fluxos principais devem passar explicitamente pelo Controller | F2: Parcial | G2: Em ProcessarOpcao(), as opções "1" e "4" chamam view.MostrarStock() e view.MostrarListaReposicao(); depois é a View que acciona PrecisoDeProdutos e PrecisoDeListaReposicao, ligados ao Model | H2: Nos fluxos de leitura, a mediação do Controller existe apenas até à chamada da View; o pedido ao Model não passa explicitamente por um handler do Controller | I2: Ou ajustar a documentação para reflectir este fluxo real, ou criar handlers explícitos no Controller para consulta e reposição | J2: Alta | K2: 46138 | L2: =B2&C2&D2&E2
A3: =_xlfn.XLOOKUP(L3,CheckT3_20260419!L:L,CheckT3_20260419!A:A) | B3: Documentação | C3: Coerência entre código e diagrama de sequência V5 | D3: Controller.cs / View.cs / diagrama V5 | E3: O fluxo implementado deve coincidir com o fluxo documentado | F3: Não conforme | G3: No código, consulta e reposição seguem Controller -> View -> Model por delegados; no diagrama V5, esses fluxos aparecem como View -> Controller -> Model | H3: Há desvio entre a implementação actual e a documentação submetida | I3: Harmonizar diagrama/documentação com o código, ou refactorizar o código para mediação explícita do Controller até ao Model | J3: Alta | K3: 46138 | L3: =B3&C3&D3&E3
A4: =_xlfn.XLOOKUP(L4,CheckT3_20260419!L:L,CheckT3_20260419!A:A) | B4: Implementação | C4: Ciclo do menu sem recursão acumulada | D4: Controller.cs / View.cs | E4: O fluxo principal não deve acumular chamadas recursivas ao menu | F4: Conforme | G4: View.MostrarMenu() passou a usar while (true) e ProcessarOpcao() já não volta a chamar view.MostrarMenu() | J4: Baixa | K4: 46138 | L4: =B4&C4&D4&E4
A5: =_xlfn.XLOOKUP(L5,CheckT3_20260419!L:L,CheckT3_20260419!A:A) | B5: Implementação | C5: Menu não duplicado em casos de erro de validação | D5: Controller.cs | E5: Em caso de erro de validação, o menu não deve ser reapresentado duas vezes | F5: Conforme | G5: Em RegistarOuAtualizarProduto() e RemoverQuantidade(), em caso de erro apenas é chamado view.MostrarErro(...) e o controlo regressa ao ciclo único do menu na View | J5: Baixa | K5: 46138 | L5: =B5&C5&D5&E5
A6: =_xlfn.XLOOKUP(L6,CheckT3_20260419!L:L,CheckT3_20260419!A:A) | B6: Implementação | C6: Métodos de consulta do Model implementados | D6: Model.cs | E6: SolicitarListaProdutos e SolicitarListaReposicao devem estar funcionais | F6: Conforme | G6: SolicitarListaProdutos copia _listaProdutos para uma nova lista; SolicitarListaReposicao filtra produtos com Quantidade < QuantidadeMinima | H6: Comentários TODO ficaram desactualizados face à implementação real | I6: Actualizar ou remover os comentários TODO | J6: Baixa | K6: 46138 | L6: =B6&C6&D6&E6
A7: =_xlfn.XLOOKUP(L7,CheckT3_20260419!L:L,CheckT3_20260419!A:A) | B7: Implementação | C7: Métodos de lógica de negócio do Model implementados | D7: Model.cs | E7: RegistarOuAtualizarProduto e RemoverQuantidade devem estar funcionais | F7: Conforme | G7: RegistarOuAtualizarProduto adiciona/actualiza produto, chama GuardarDados() e dispara OperacaoConcluida; RemoverQuantidade valida stock, remove, guarda e notifica sucesso/erro | H7: Comentários TODO ficaram desactualizados face à implementação real | I7: Actualizar ou remover os comentários TODO | J7: Baixa | K7: 46138 | L7: =B7&C7&D7&E7
A8: =_xlfn.XLOOKUP(L8,CheckT3_20260419!L:L,CheckT3_20260419!A:A) | B8: Implementação | C8: Persistência JSON implementada | D8: Model.cs | E8: CarregarDados e GuardarDados devem estar funcionais | F8: Conforme | G8: CarregarDados() lê produtos.json e usa JsonConvert.DeserializeObject; GuardarDados() serializa com JsonConvert.SerializeObject e escreve em ficheiro | H8: Comentários TODO ficaram desactualizados face à implementação real | I8: Actualizar ou remover os comentários TODO | J8: Baixa | K8: 46138 | L8: =B8&C8&D8&E8
A9: =_xlfn.XLOOKUP(L9,CheckT3_20260419!L:L,CheckT3_20260419!A:A) | B9: Implementação | C9: Dependência da API JSON declarada no projecto | D9: GestorStockDomestico.csproj | E9: O projecto deve declarar a dependência necessária para Json.NET, se a persistência a usar for mesmo essa | F9: Conforme | G9: Existe <PackageReference Include="Newtonsoft.Json" Version="13.0.3" /> | J9: Baixa | K9: 46138 | L9: =B9&C9&D9&E9
A10: =_xlfn.XLOOKUP(L10,CheckT3_20260419!L:L,CheckT3_20260419!A:A) | B10: Implementação | C10: Pasta de testes preparada | D10: tests/README.md | E10: A área de testes deve ter pelo menos estrutura mínima identificada | F10: Conforme | G10: Existe a pasta tests com README.md a identificar o espaço para testes, casos de teste, resultados e apoio ao verificador | H10: Ainda não há artefactos reais de testes dentro da pasta, apenas a estrutura mínima | I10: Avançar para criação dos ficheiros e registos de testes quando os testes começarem a ser executados | J10: Média | K10: 46138 | L10: =B10&C10&D10&E10
A11: 32 | B11: Testes | C11: Testabilidade da View | D11: View.cs | E11: A View deve manter-se focada em input/output para não dificultar validação posterior. | F11: Conforme | G11: A View está focada em leitura de input, apresentação de output e emissão de eventos; não contém lógica de negócio | J11: Baixa | K11: 46138 | L11: =B11&C11&D11&E11

Sheet CheckT3_20260427
A1: ID# | B1: Área | C1: Aspecto verificado | D1: Ficheiro/Local | E1: Critério | F1: Estado | G1: Evidência | H1: Problema detectado | I1: Correcção sugerida | J1: Prioridade | K1: Data
A2: 1 | B2: MVC | C2: Arranque da aplicação | D2: Program.cs | E2: Program apenas arranca o Controller | F2: Conforme | G2: Controller controller = new Controller(); controller.IniciarPrograma(); | J2: Baixa | K2: 46131 | L2: MVCArranque da aplicaçãoProgram.csProgram apenas arranca o Controller
A3: 2 | B3: MVC | C3: Arranque no Controller | D3: Controller.cs | E3: O ciclo da aplicação deve iniciar no Controller e passar para a View | F3: Conforme | G3: IniciarPrograma() chama view.MostrarMenu(); | J3: Baixa | K3: 46131 | L3: MVCArranque no ControllerController.csO ciclo da aplicação deve iniciar no Controller e passar para a View
A4: 3 | B4: MVC | C4: Controller como ponto central de ligação | D4: Controller.cs | E4: O Controller deve instanciar e ligar View e Model | F4: Conforme | G4: Instancia view e model, carrega dados e faz todas as subscrições no construtor | J4: Baixa | K4: 46131 | L4: MVCController como ponto central de ligaçãoController.csO Controller deve instanciar e ligar View e Model
A5: 4 | B5: MVC | C5: Input entra na View | D5: View.cs | E5: A variante Curry & Grace exige input na View | F5: Conforme | G5: MostrarMenu, PedirDadosProduto e PedirRemocaoQuantidade recolhem o input do utilizador | J5: Baixa | K5: 46131 | L5: MVCInput entra na ViewView.csA variante Curry & Grace exige input na View
A6: 5 | B6: MVC | C6: View não conhece directamente o Model | D6: View.cs | E6: A View não deve instanciar nem referenciar directamente o Model | F6: Conforme | G6: View.cs não instancia nem usa a classe Model; apenas expõe eventos/delegados | J6: Baixa | K6: 46131 | L6: MVCView não conhece directamente o ModelView.csA View não deve instanciar nem referenciar directamente o Model
A7: 6 | B7: MVC | C7: Model não conhece View nem Controller | D7: Model.cs | E7: O Model não deve depender de View nem Controller | F7: Conforme | G7: Model.cs não referencia View nem Controller | J7: Baixa | K7: 46131 | L7: MVCModel não conhece View nem ControllerModel.csO Model não deve depender de View nem Controller
A8: 7 | B8: MVC | C8: Saída apresentada pela View | D8: View.cs | E8: Os resultados devem ser apresentados na View | F8: Conforme | G8: MostrarStock, MostrarListaReposicao, MostrarConfirmacao, MostrarErro, MostrarMensagemFinal | J8: Baixa | K8: 46131 | L8: MVCSaída apresentada pela ViewView.csOs resultados devem ser apresentados na View
A9: 8 | B9: MVC | C9: Papel do Controller limitado à coordenação | D9: Controller.cs | E9: O Controller não deve conter lógica de negócio do domínio | F9: Conforme | G9: Faz encaminhamento, validação básica e coordenação; não implementa regras de stock nem persistência | J9: Baixa | K9: 46131 | L9: MVCPapel do Controller limitado à coordenaçãoController.csO Controller não deve conter lógica de negócio do domínio
A10: 9 | B10: Eventos/Delegados | C10: Input da View chega ao Controller por eventos | D10: Controller.cs | E10: Os inputs do utilizador devem ser recebidos pelo Controller via eventos | F10: Conforme | G10: view.OpcaoSelecionada += ProcessarOpcao;, view.DadosProdutoIntroduzidos += RegistarOuAtualizarProduto;, view.RemocaoSolicitada += RemoverQuantidade; | J10: Baixa | K10: 46131 | L10: Eventos/DelegadosInput da View chega ao Controller por eventosController.csOs inputs do utilizador devem ser recebidos pelo Controller via eventos
A11: 10 | B11: Eventos/Delegados | C11: Pedidos de consulta e reposição estão ligados por delegados | D11: Controller.cs / View.cs | E11: Os pedidos de leitura devem estar formalmente ligados no arranque | F11: Conforme | G11: view.PrecisoDeProdutos += model.SolicitarListaProdutos; e view.PrecisoDeListaReposicao += model.SolicitarListaReposicao; | H11: Este encadeamento contribui para o desvio face ao diagrama V5 nos fluxos de consulta e reposição | I11: Clarificar documentalmente este fluxo ou passar também estes pedidos por handlers explícitos no Controller | J11: Média | K11: 46131 | L11: Eventos/DelegadosPedidos de consulta e reposição estão ligados por delegadosController.cs / View.csOs pedidos de leitura devem estar formalmente ligados no arranque
A12: 11 | B12: Eventos/Delegados | C12: Notificações do Model chegam à View por eventos | D12: Controller.cs | E12: As respostas do Model devem chegar à View por eventos | F12: Conforme | G12: model.OperacaoConcluida += view.MostrarConfirmacao;, model.ErroStockInsuficiente += view.MostrarErro; | J12: Baixa | K12: 46131 | L12: Eventos/DelegadosNotificações do Model chegam à View por eventosController.csAs respostas do Model devem chegar à View por eventos
A13: 12 | B13: Eventos/Delegados | C13: Invocação segura de eventos na View | D13: View.cs | E13: A View deve invocar eventos com verificação nula | F13: Conforme | G13: Uso de ?.Invoke(...) nos eventos de input | J13: Baixa | K13: 46131 | L13: Eventos/DelegadosInvocação segura de eventos na ViewView.csA View deve invocar eventos com verificação nula
A14: 13 | B14: Acoplamento | C14: Ausência de acoplamento estrutural View -> Model | D14: View.cs | E14: A View não deve criar nem conhecer o Model | F14: Conforme | G14: A View apenas expõe contratos de comunicação; não conhece a implementação do Model | J14: Baixa | K14: 46131 | L14: AcoplamentoAusência de acoplamento estrutural View -> ModelView.csA View não deve criar nem conhecer o Model
A15: 14 | B15: Acoplamento | C15: Ausência de acoplamento estrutural Model -> View/Controller | D15: Model.cs | E15: O Model deve estar isolado dos outros componentes | F15: Conforme | G15: O Model apenas expõe eventos e métodos próprios | J15: Baixa | K15: 46131 | L15: AcoplamentoAusência de acoplamento estrutural Model -> View/ControllerModel.csO Model deve estar isolado dos outros componentes
A16: 15 | B16: Acoplamento | C16: Mediação explícita do Controller nos fluxos de leitura | D16: Controller.cs / arquitectura | E16: Os fluxos principais devem passar explicitamente pelo Controller | F16: Parcial | G16: Em ProcessarOpcao(), as opções "1" e "4" chamam view.MostrarStock() e view.MostrarListaReposicao(); depois é a View que acciona PrecisoDeProdutos e PrecisoDeListaReposicao, ligados ao Model | H16: Nos fluxos de leitura, a mediação do Controller existe apenas até à chamada da View; o pedido ao Model não passa explicitamente por um handler do Controller | I16: Ou ajustar a documentação para reflectir este fluxo real, ou criar handlers explícitos no Controller para consulta e reposição | J16: Alta | K16: 46138 | L16: AcoplamentoMediação explícita do Controller nos fluxos de leituraController.cs / arquitecturaOs fluxos principais devem passar explicitamente pelo Controller
A17: 16 | B17: Documentação | C17: Coerência com a variante Curry & Grace adoptada | D17: Código + decisão da equipa | E17: O código deve manter input na View e coordenação geral no Controller | F17: Conforme | G17: O padrão geral do código respeita a decisão arquitectónica assumida | J17: Baixa | K17: 46131 | L17: DocumentaçãoCoerência com a variante Curry & Grace adoptadaCódigo + decisão da equipaO código deve manter input na View e coordenação geral no Controller
A18: 17 | B18: Documentação | C18: Coerência entre código e diagrama de sequência V5 | D18: Controller.cs / View.cs / diagrama V5 | E18: O fluxo implementado deve coincidir com o fluxo documentado | F18: Não conforme | G18: No código, consulta e reposição seguem Controller -> View -> Model por delegados; no diagrama V5, esses fluxos aparecem como View -> Controller -> Model | H18: Há desvio entre a implementação actual e a documentação submetida | I18: Harmonizar diagrama/documentação com o código, ou refactorizar o código para mediação explícita do Controller até ao Model | J18: Alta | K18: 46138 | L18: DocumentaçãoCoerência entre código e diagrama de sequência V5Controller.cs / View.cs / diagrama V5O fluxo implementado deve coincidir com o fluxo documentado
A19: 18 | B19: Implementação | C19: Estrutura base do Controller implementada | D19: Controller.cs | E19: O Controller deve estar funcional ao nível do arranque, coordenação e encerramento | F19: Conforme | G19: Construtor, handlers, IniciarPrograma() e Encerrar() estão implementados | H19: Encerrar() usa Environment.Exit(0), o que dificulta a execução de testes automáticos e de integração no próprio projecto | I19: Substituir por mecanismo de fecho controlado quando se avançar para a fase de testes | J19: Média | K19: 46131 | L19: ImplementaçãoEstrutura base do Controller implementadaController.csO Controller deve estar funcional ao nível do arranque, coordenação e encerramento
A20: 19 | B20: Implementação | C20: Ciclo do menu sem recursão acumulada | D20: Controller.cs / View.cs | E20: O fluxo principal não deve acumular chamadas recursivas ao menu | F20: Conforme | G20: View.MostrarMenu() passou a usar while (true) e ProcessarOpcao() já não volta a chamar view.MostrarMenu() | J20: Baixa | K20: 46138 | L20: ImplementaçãoCiclo do menu sem recursão acumuladaController.cs / View.csO fluxo principal não deve acumular chamadas recursivas ao menu
A21: 20 | B21: Implementação | C21: Menu não duplicado em casos de erro de validação | D21: Controller.cs | E21: Em caso de erro de validação, o menu não deve ser reapresentado duas vezes | F21: Conforme | G21: Em RegistarOuAtualizarProduto() e RemoverQuantidade(), em caso de erro apenas é chamado view.MostrarErro(...) e o controlo regressa ao ciclo único do menu na View | J21: Baixa | K21: 46138 | L21: ImplementaçãoMenu não duplicado em casos de erro de validaçãoController.csEm caso de erro de validação, o menu não deve ser reapresentado duas vezes
A22: 21 | B22: Implementação | C22: Estrutura base da View implementada | D22: View.cs | E22: A View deve suportar menu, recolha de input e apresentação de output | F22: Conforme | G22: Métodos principais da interface de consola estão implementados | J22: Baixa | K22: 46131 | L22: ImplementaçãoEstrutura base da View implementadaView.csA View deve suportar menu, recolha de input e apresentação de output
A23: 22 | B23: Implementação | C23: Leitura válida de inteiros na View | D23: View.cs | E23: A View deve validar input numérico básico | F23: Conforme | G23: LerInteiro() implementado com repetição até valor válido | J23: Baixa | K23: 46131 | L23: ImplementaçãoLeitura válida de inteiros na ViewView.csA View deve validar input numérico básico
A24: 23 | B24: Implementação | C24: Classe de dados Produto definida | D24: Produto.cs | E24: Deve existir uma estrutura de dados para o domínio | F24: Conforme | G24: Classe com Nome, Quantidade, QuantidadeMinima e Unidade | J24: Baixa | K24: 46131 | L24: ImplementaçãoClasse de dados Produto definidaProduto.csDeve existir uma estrutura de dados para o domínio
A25: 24 | B25: Implementação | C25: Métodos de consulta do Model implementados | D25: Model.cs | E25: SolicitarListaProdutos e SolicitarListaReposicao devem estar funcionais | F25: Conforme | G25: SolicitarListaProdutos copia _listaProdutos para uma nova lista; SolicitarListaReposicao filtra produtos com Quantidade < QuantidadeMinima | H25: Comentários TODO ficaram desactualizados face à implementação real | I25: Actualizar ou remover os comentários TODO | J25: Baixa | K25: 46138 | L25: ImplementaçãoMétodos de consulta do Model implementadosModel.csSolicitarListaProdutos e SolicitarListaReposicao devem estar funcionais
A26: 25 | B26: Implementação | C26: Métodos de lógica de negócio do Model implementados | D26: Model.cs | E26: RegistarOuAtualizarProduto e RemoverQuantidade devem estar funcionais | F26: Conforme | G26: RegistarOuAtualizarProduto adiciona/actualiza produto, chama GuardarDados() e dispara OperacaoConcluida; RemoverQuantidade valida stock, remove, guarda e notifica sucesso/erro | H26: Comentários TODO ficaram desactualizados face à implementação real | I26: Actualizar ou remover os comentários TODO | J26: Baixa | K26: 46138 | L26: ImplementaçãoMétodos de lógica de negócio do Model implementadosModel.csRegistarOuAtualizarProduto e RemoverQuantidade devem estar funcionais
A27: 26 | B27: Implementação | C27: Persistência JSON implementada | D27: Model.cs | E27: CarregarDados e GuardarDados devem estar funcionais | F27: Conforme | G27: CarregarDados() lê produtos.json e usa JsonConvert.DeserializeObject; GuardarDados() serializa com JsonConvert.SerializeObject e escreve em ficheiro | H27: Comentários TODO ficaram desactualizados face à implementação real | I27: Actualizar ou remover os comentários TODO | J27: Baixa | K27: 46138 | L27: ImplementaçãoPersistência JSON implementadaModel.csCarregarDados e GuardarDados devem estar funcionais
A28: 27 | B28: Implementação | C28: Dependência da API JSON declarada no projecto | D28: GestorStockDomestico.csproj | E28: O projecto deve declarar a dependência necessária para Json.NET, se a persistência a usar for mesmo essa | F28: Conforme | G28: Existe <PackageReference Include="Newtonsoft.Json" Version="13.0.3" /> | J28: Baixa | K28: 46138 | L28: ImplementaçãoDependência da API JSON declarada no projectoGestorStockDomestico.csprojO projecto deve declarar a dependência necessária para Json.NET, se a persistência a usar for mesmo essa
A29: 28 | B29: Implementação | C29: Pasta de testes preparada | D29: tests/README.md | E29: A área de testes deve ter pelo menos estrutura mínima identificada | F29: Conforme | G29: Existe a pasta tests com README.md a identificar o espaço para testes, casos de teste, resultados e apoio ao verificador | H29: Ainda não há artefactos reais de testes dentro da pasta, apenas a estrutura mínima | I29: Avançar para criação dos ficheiros e registos de testes quando os testes começarem a ser executados | J29: Média | K29: 46138 | L29: ImplementaçãoPasta de testes preparadatests/README.mdA área de testes deve ter pelo menos estrutura mínima identificada
A30: 29 | B30: Testes | C30: Plano de testes unitários | D30: Registo do Verificador | E30: Devem estar definidos casos de teste para Controller e Model | F30: Em preparação | G30: Já é possível identificar operações críticas do Controller e do Model | H30: A matriz ainda não está formalizada | I30: Fechar a matriz de testes unitários no Excel/ficheiro de apoio | J30: Média | K30: 46131 | L30: TestesPlano de testes unitáriosRegisto do VerificadorDevem estar definidos casos de teste para Controller e Model
A31: 30 | B31: Testes | C31: Testes unitários do Controller executados | D31: Próprio projecto | E31: Deve existir validação do encaminhamento e subscrição dos fluxos | F31: Não executado nesta fase | G31: Ainda não existem métodos/casos/resultados de teste integrados no código actual | H31: O trabalho de testes ainda não arrancou formalmente | I31: Executar após fecho mínimo dos fluxos e definição dos cenários | J31: Média | K31: 46131 | L31: TestesTestes unitários do Controller executadosPróprio projectoDeve existir validação do encaminhamento e subscrição dos fluxos
A32: 31 | B32: Testes | C32: Testes unitários do Model executados | D32: Próprio projecto | E32: Deve existir validação da lógica de negócio e persistência | F32: Não executado nesta fase | G32: Os métodos críticos do Model continuam por implementar | H32: O estado actual do Model impede testes unitários úteis | I32: Executar após implementação mínima funcional | J32: Média | K32: 46131 | L32: TestesTestes unitários do Model executadosPróprio projectoDeve existir validação da lógica de negócio e persistência
A33: 32 | B33: Testes | C33: Testabilidade da View | D33: View.cs | E33: A View deve manter-se focada em input/output para não dificultar validação posterior. | F33: Conforme | G33: A View está focada em leitura de input, apresentação de output e emissão de eventos; não contém lógica de negócio | J33: Baixa | K33: 46138 | L33: TestesTestabilidade da ViewView.csA View deve manter-se focada em input/output para não dificultar validação posterior
A34: 33 | B34: Testes | C34: Plano de testes de integração | D34: Registo do Verificador | E34: Devem estar definidos cenários View -> Controller -> Model -> View | F34: Em preparação | G34: Os cenários já podem ser identificados a partir do protótipo e do diagrama | H34: Ainda falta formalizar e calendarizar a execução | I34: Definir cenários de consulta, registo, remoção, erro, reposição e saída | J34: Média | K34: 46131 | L34: TestesPlano de testes de integraçãoRegisto do VerificadorDevem estar definidos cenários View -> Controller -> Model -> View
A35: 34 | B35: Testes | C35: Testes de integração executados | D35: Próprio projecto | E35: Os fluxos principais devem ser validados ponta-a-ponta | F35: Não executado nesta fase | G35: A integração estrutural existe, mas a implementação está incompleta e há desvio com a documentação | H35: Ainda não há base estável para validação integrada formal | I35: Executar após fecho funcional mínimo e harmonização código-documentação | J35: Média | K35: 46131 | L35: TestesTestes de integração executadosPróprio projectoOs fluxos principais devem ser validados ponta-a-ponta

Sheet CheckT4_20260430
A1: ID# | B1: Área | C1: Aspecto verificado | D1: Ficheiro/Local | E1: Critério | F1: Estado | G1: Evidência | H1: Problema detectado | I1: Correcção sugerida | J1: Prioridade | K1: Data
A2: 1 | B2: MVC | C2: Arranque da aplicação | D2: Program.cs | E2: Program apenas arranca o Controller | F2: Conforme | G2: Controller controller = new Controller(); controller.IniciarPrograma(); | J2: Baixa | K2: 46131 | L2: MVCArranque da aplicaçãoProgram.csProgram apenas arranca o Controller
A3: 2 | B3: MVC | C3: Arranque no Controller | D3: Controller.cs | E3: O ciclo da aplicação deve iniciar no Controller e passar para a View | F3: Conforme | G3: IniciarPrograma() chama view.MostrarMenu(); | J3: Baixa | K3: 46131 | L3: MVCArranque no ControllerController.csO ciclo da aplicação deve iniciar no Controller e passar para a View
A4: 3 | B4: MVC | C4: Controller como ponto central de ligação | D4: Controller.cs | E4: O Controller deve instanciar e ligar View e Model | F4: Conforme | G4: Instancia view e model, carrega dados e faz todas as subscrições no construtor | J4: Baixa | K4: 46131 | L4: MVCController como ponto central de ligaçãoController.csO Controller deve instanciar e ligar View e Model
A5: 4 | B5: MVC | C5: Input entra na View | D5: View.cs | E5: A variante Curry & Grace exige input na View | F5: Conforme | G5: MostrarMenu, PedirDadosProduto e PedirRemocaoQuantidade recolhem o input do utilizador | J5: Baixa | K5: 46131 | L5: MVCInput entra na ViewView.csA variante Curry & Grace exige input na View
A6: 5 | B6: MVC | C6: View não conhece directamente o Model | D6: View.cs | E6: A View não deve instanciar nem referenciar directamente o Model | F6: Conforme | G6: View.cs não instancia nem usa a classe Model; apenas expõe eventos/delegados | J6: Baixa | K6: 46131 | L6: MVCView não conhece directamente o ModelView.csA View não deve instanciar nem referenciar directamente o Model
A7: 6 | B7: MVC | C7: Model não conhece View nem Controller | D7: Model.cs | E7: O Model não deve depender de View nem Controller | F7: Conforme | G7: Model.cs não referencia View nem Controller | J7: Baixa | K7: 46131 | L7: MVCModel não conhece View nem ControllerModel.csO Model não deve depender de View nem Controller
A8: 7 | B8: MVC | C8: Saída apresentada pela View | D8: View.cs | E8: Os resultados devem ser apresentados na View | F8: Conforme | G8: MostrarStock, MostrarListaReposicao, MostrarConfirmacao, MostrarErro, MostrarMensagemFinal | J8: Baixa | K8: 46131 | L8: MVCSaída apresentada pela ViewView.csOs resultados devem ser apresentados na View
A9: 8 | B9: MVC | C9: Papel do Controller limitado à coordenação | D9: Controller.cs | E9: O Controller não deve conter lógica de negócio do domínio | F9: Conforme | G9: Faz encaminhamento, validação básica e coordenação; não implementa regras de stock nem persistência | J9: Baixa | K9: 46131 | L9: MVCPapel do Controller limitado à coordenaçãoController.csO Controller não deve conter lógica de negócio do domínio
A10: 9 | B10: Eventos/Delegados | C10: Input da View chega ao Controller por eventos | D10: Controller.cs | E10: Os inputs do utilizador devem ser recebidos pelo Controller via eventos | F10: Conforme | G10: view.OpcaoSelecionada += ProcessarOpcao;, view.DadosProdutoIntroduzidos += RegistarOuAtualizarProduto;, view.RemocaoSolicitada += RemoverQuantidade; | J10: Baixa | K10: 46131 | L10: Eventos/DelegadosInput da View chega ao Controller por eventosController.csOs inputs do utilizador devem ser recebidos pelo Controller via eventos
A11: 10 | B11: Eventos/Delegados | C11: Pedidos de consulta e reposição estão ligados por delegados | D11: Controller.cs / View.cs | E11: Os pedidos de leitura devem estar formalmente ligados no arranque | F11: Não conforme | G11: No código actual, os fluxos de leitura são tratados por métodos explícitos do Controller (MostrarStock e MostrarListaReposicao) e não por delegados ligados no arranque | H11: A linha de verificação deixou de corresponder à implementação actual | I11: Actualizar esta verificação para reflectir a mediação explícita do Controller nos fluxos de leitura | J11: Média | K11: 46143 | L11: Eventos/DelegadosPedidos de consulta e reposição estão ligados por delegadosController.cs / View.csOs pedidos de leitura devem estar formalmente ligados no arranque
A12: 11 | B12: Eventos/Delegados | C12: Notificações do Model chegam à View por eventos | D12: Controller.cs | E12: As respostas do Model devem chegar à View por eventos | F12: Conforme | G12: model.OperacaoConcluida += view.MostrarConfirmacao;, model.ErroStockInsuficiente += view.MostrarErro; | J12: Baixa | K12: 46131 | L12: Eventos/DelegadosNotificações do Model chegam à View por eventosController.csAs respostas do Model devem chegar à View por eventos
A13: 12 | B13: Eventos/Delegados | C13: Invocação segura de eventos na View | D13: View.cs | E13: A View deve invocar eventos com verificação nula | F13: Conforme | G13: Uso de ?.Invoke(...) nos eventos de input | J13: Baixa | K13: 46131 | L13: Eventos/DelegadosInvocação segura de eventos na ViewView.csA View deve invocar eventos com verificação nula
A14: 13 | B14: Acoplamento | C14: Ausência de acoplamento estrutural View -> Model | D14: View.cs | E14: A View não deve criar nem conhecer o Model | F14: Conforme | G14: A View apenas expõe contratos de comunicação; não conhece a implementação do Model | J14: Baixa | K14: 46131 | L14: AcoplamentoAusência de acoplamento estrutural View -> ModelView.csA View não deve criar nem conhecer o Model
A15: 14 | B15: Acoplamento | C15: Ausência de acoplamento estrutural Model -> View/Controller | D15: Model.cs | E15: O Model deve estar isolado dos outros componentes | F15: Conforme | G15: O Model apenas expõe eventos e métodos próprios | J15: Baixa | K15: 46131 | L15: AcoplamentoAusência de acoplamento estrutural Model -> View/ControllerModel.csO Model deve estar isolado dos outros componentes
A16: 15 | B16: Acoplamento | C16: Mediação explícita do Controller nos fluxos de leitura | D16: Controller.cs / arquitectura | E16: Os fluxos principais devem passar explicitamente pelo Controller | F16: Conforme | G16: Em ProcessarOpcao(), as opções "1" e "4" chamam métodos explícitos do Controller (MostrarStock e MostrarListaReposicao), que obtêm os dados do Model e os passam à View | J16: Baixa | K16: 46143 | L16: AcoplamentoMediação explícita do Controller nos fluxos de leituraController.cs / arquitecturaOs fluxos principais devem passar explicitamente pelo Controller
A17: 16 | B17: Documentação | C17: Coerência com a variante Curry & Grace adoptada | D17: Código + decisão da equipa | E17: O código deve manter input na View e coordenação geral no Controller | F17: Conforme | G17: O padrão geral do código respeita a decisão architectónica assumida | J17: Baixa | K17: 46131 | L17: DocumentaçãoCoerência com a variante Curry & Grace adoptadaCódigo + decisão da equipaO código deve manter input na View e coordenação geral no Controller
A18: 17 | B18: Documentação | C18: Coerência entre código e diagrama de sequência V5 | D18: Controller.cs / View.cs / diagrama V5 | E18: O fluxo implementado deve coincidir com o fluxo documentado | F18: Conforme | G18: No código actual, o input entra na View, passa ao Controller por evento e os fluxos de leitura são mediados explicitamente pelo Controller antes da chamada ao Model | J18: Baixa | K18: 46143 | L18: DocumentaçãoCoerência entre código e diagrama de sequência V5Controller.cs / View.cs / diagrama V5O fluxo implementado deve coincidir com o fluxo documentado
A19: 18 | B19: Implementação | C19: Estrutura base do Controller implementada | D19: Controller.cs | E19: O Controller deve estar funcional ao nível do arranque, coordenação e encerramento | F19: Conforme | G19: Construtor, handlers, IniciarPrograma() e Encerrar() estão implementados; o fecho é feito com _executando = false | J19: Baixa | K19: 46143 | L19: ImplementaçãoEstrutura base do Controller implementadaController.csO Controller deve estar funcional ao nível do arranque, coordenação e encerramento
A20: 19 | B20: Implementação | C20: Ciclo do menu sem recursão acumulada | D20: Controller.cs / View.cs | E20: O fluxo principal não deve acumular chamadas recursivas ao menu | F20: Conforme | G20: View.MostrarMenu() passou a usar while (true) e ProcessarOpcao() já não volta a chamar view.MostrarMenu() | J20: Baixa | K20: 46138 | L20: ImplementaçãoCiclo do menu sem recursão acumuladaController.cs / View.csO fluxo principal não deve acumular chamadas recursivas ao menu
A21: 20 | B21: Implementação | C21: Menu não duplicado em casos de erro de validação | D21: Controller.cs | E21: Em caso de erro de validação, o menu não deve ser reapresentado duas vezes | F21: Conforme | G21: Em RegistarOuAtualizarProduto() e RemoverQuantidade(), em caso de erro apenas é chamado view.MostrarErro(...) e o controlo regressa ao ciclo único do menu na View | J21: Baixa | K21: 46138 | L21: ImplementaçãoMenu não duplicado em casos de erro de validaçãoController.csEm caso de erro de validação, o menu não deve ser reapresentado duas vezes
A22: 21 | B22: Implementação | C22: Estrutura base da View implementada | D22: View.cs | E22: A View deve suportar menu, recolha de input e apresentação de output | F22: Conforme | G22: Métodos principais da interface de consola estão implementados | J22: Baixa | K22: 46131 | L22: ImplementaçãoEstrutura base da View implementadaView.csA View deve suportar menu, recolha de input e apresentação de output
A23: 22 | B23: Implementação | C23: Leitura válida de inteiros na View | D23: View.cs | E23: A View deve validar input numérico básico | F23: Conforme | G23: LerInteiro() implementado com repetição até valor válido | J23: Baixa | K23: 46131 | L23: ImplementaçãoLeitura válida de inteiros na ViewView.csA View deve validar input numérico básico
A24: 23 | B24: Implementação | C24: Classe de dados Produto definida | D24: Produto.cs | E24: Deve existir uma estrutura de dados para o domínio | F24: Conforme | G24: Classe com Nome, Quantidade, QuantidadeMinima e Unidade | J24: Baixa | K24: 46131 | L24: ImplementaçãoClasse de dados Produto definidaProduto.csDeve existir uma estrutura de dados para o domínio
A25: 24 | B25: Implementação | C25: Métodos de consulta do Model implementados | D25: Model.cs | E25: SolicitarListaProdutos e SolicitarListaReposicao devem estar funcionais | F25: Conforme | G25: SolicitarListaProdutos copia _listaProdutos para uma nova lista; SolicitarListaReposicao filtra produtos com Quantidade < QuantidadeMinima | H25: Comentários TODO ficaram desactualizados face à implementação real | I25: Actualizar ou remover os comentários TODO | J25: Baixa | K25: 46138 | L25: ImplementaçãoMétodos de consulta do Model implementadosModel.csSolicitarListaProdutos e SolicitarListaReposicao devem estar funcionais
A26: 25 | B26: Implementação | C26: Métodos de lógica de negócio do Model implementados | D26: Model.cs | E26: RegistarOuAtualizarProduto e RemoverQuantidade devem estar funcionais | F26: Conforme | G26: RegistarOuAtualizarProduto adiciona/actualiza produto, chama GuardarDados() e dispara OperacaoConcluida; RemoverQuantidade valida stock, remove, guarda e notifica sucesso/erro | H26: Comentários TODO ficaram desactualizados face à implementação real | I26: Actualizar ou remover os comentários TODO | J26: Baixa | K26: 46138 | L26: ImplementaçãoMétodos de lógica de negócio do Model implementadosModel.csRegistarOuAtualizarProduto e RemoverQuantidade devem estar funcionais
A27: 26 | B27: Implementação | C27: Persistência JSON implementada | D27: Model.cs | E27: CarregarDados e GuardarDados devem estar funcionais | F27: Conforme | G27: CarregarDados() lê produtos.json e usa JsonConvert.DeserializeObject; GuardarDados() serializa com JsonConvert.SerializeObject e escreve em ficheiro | H27: Comentários TODO ficaram desactualizados face à implementação real | I27: Actualizar ou remover os comentários TODO | J27: Baixa | K27: 46138 | L27: ImplementaçãoPersistência JSON implementadaModel.csCarregarDados e GuardarDados devem estar funcionais
A28: 27 | B28: Implementação | C28: Dependência da API JSON declarada no projecto | D28: GestorStockDomestico.csproj | E28: O projecto deve declarar a dependência necessária para Json.NET, se a persistência a usar for mesmo essa | F28: Conforme | G28: Existe <PackageReference Include="Newtonsoft.Json" Version="13.0.3" /> | J28: Baixa | K28: 46138 | L28: ImplementaçãoDependência da API JSON declarada no projectoGestorStockDomestico.csprojO projecto deve declarar a dependência necessária para Json.NET, se a persistência a usar for mesmo essa
A29: 28 | B29: Implementação | C29: Pasta de testes preparada | D29: tests/README.md | E29: A área de testes deve ter pelo menos estrutura mínima identificada | F29: Conforme | G29: Existe a pasta tests com README.md a identificar o espaço para testes, casos de teste, resultados e apoio ao verificador | H29: Ainda não há artefactos reais de testes dentro da pasta, apenas a estrutura mínima | I29: Avançar para criação dos ficheiros e registos de testes quando os testes começarem a ser executados | J29: Média | K29: 46138 | L29: ImplementaçãoPasta de testes preparadatests/README.mdA área de testes deve ter pelo menos estrutura mínima identificada
A30: 29 | B30: Testes | C30: Plano de testes unitários | D30: Registo do Verificador | E30: Devem estar definidos casos de teste para Controller e Model | F30: Conforme | G30: O plano final actualizado já inclui testes unitários para Controller e Model, além de View | J30: Baixa | K30: 46143 | L30: TestesPlano de testes unitáriosRegisto do VerificadorDevem estar definidos casos de teste para Controller e Model
A31: 30 | B31: Testes | C31: Testes unitários do Controller executados | D31: Próprio projecto | E31: Deve existir validação do encaminhamento e subscrição dos fluxos | F31: Não executado nesta fase | G31: Não existem ainda registos formais de execução isolada do Controller | H31: O trabalho formal de execução dos testes unitários do Controller ainda não arrancou | I31: Executar e registar cenários do plano final | J31: Alta | K31: 46143 | L31: TestesTestes unitários do Controller executadosPróprio projectoDeve existir validação do encaminhamento e subscrição dos fluxos
A32: 31 | B32: Testes | C32: Testes unitários do Model executados | D32: Próprio projecto | E32: Deve existir validação da lógica de negócio e persistência | F32: Não executado nesta fase | G32: Não existem ainda registos formais de execução isolada do Model | H32: O trabalho formal de execução dos testes unitários do Model ainda não arrancou | I32: Executar e registar cenários do plano final | J32: Alta | K32: 46143 | L32: TestesTestes unitários do Model executadosPróprio projectoDeve existir validação da lógica de negócio e persistência
A33: 32 | B33: Testes | C33: Testabilidade da View | D33: View.cs | E33: A View deve manter-se focada em input/output para não dificultar validação posterior. | F33: Conforme | G33: A View está focada em leitura de input, apresentação de output e emissão de eventos; não contém lógica de negócio | J33: Baixa | K33: 46138 | L33: TestesTestabilidade da ViewView.csA View deve manter-se focada em input/output para não dificultar validação posterior
A34: 33 | B34: Testes | C34: Plano de testes de integração | D34: Registo do Verificador | E34: Devem estar definidos cenários View -> Controller -> Model -> View | F34: Conforme | G34: O plano final actualizado já inclui testes de integração de baixo para cima e de explosão | J34: Baixa | K34: 46143 | L34: TestesPlano de testes de integraçãoRegisto do VerificadorDevem estar definidos cenários View -> Controller -> Model -> View
A35: 34 | B35: Testes | C35: Testes de integração executados | D35: Próprio projecto | E35: Os fluxos principais devem ser validados ponta-a-ponta | F35: Não executado nesta fase | G35: Não existem ainda registos formais completos de execução dos testes de integração no projecto | H35: A execução formal dos testes de integração ainda não arrancou | I35: Executar e registar os cenários do plano final | J35: Alta | K35: 46143 | L35: TestesTestes de integração executadosPróprio projectoOs fluxos principais devem ser validados ponta-a-ponta
A36: 35 | B36: Testes | C36: Mapear os testes: plano final actualizado e categorizado | D36: Testes.xlsx / Plano de Testes | E36: O plano de testes deve reflectir a divisão final em 5 categorias e preservar IDs, tipos e restantes atributos definidos | F36: Conforme | G36: O plano final já distingue Testes Estáticos, Testes Unitários Dinâmicos – Caixa Fechada, Testes Unitários Dinâmicos – Caixa Aberta, Testes de Integração – De Baixo para Cima e Testes de Integração – Explosão, com IDs e tipos preenchidos | J36: Baixa | K36: 46141
A37: 36 | B37: Testes | C37: Plano de testes estáticos definido | D37: Testes.xlsx / Plano de Testes | E37: Devem existir testes estáticos para Model, Controller, View, Arquitectura MVC, Excepções e Persistência | F37: Conforme | G37: MS1-MS4, CS1-CS4, VS1-VS4 e GES1-GES5 estão definidos | J37: Baixa | K37: 46141
A38: 37 | B38: Testes | C38: Plano de testes unitários dinâmicos – caixa fechada definido | D38: Testes.xlsx / Plano de Testes | E38: Devem existir testes de View, Controller e Model para comportamento observável | F38: Conforme | G38: VU1-VU5, CU2/CU5/CU6/CU7, GUV1-GUV4/GUV10, GUC2-GUC3 e GUM1-GUM5/GUM8 estão definidos | J38: Baixa | K38: 46141
A39: 38 | B39: Testes | C39: Plano de testes unitários dinâmicos – caixa aberta definido | D39: Testes.xlsx / Plano de Testes | E39: Devem existir testes que validem eventos, estado interno, persistência e propagação de erros | F39: Conforme | G39: MU5-MU7, VU6-VU8, CU8-CU11, GUV5-GUV7 e GUM6-GUM7 estão definidos | J39: Baixa | K39: 46141
A40: 39 | B40: Testes | C40: Plano de testes de integração – de baixo para cima definido | D40: Testes.xlsx / Plano de Testes | E40: Devem existir testes de integração incremental entre Model, Controller, View e Persistência | F40: Conforme | G40: MI1, VI1, CI1, CI2, CI4 e GIB2-GIB5 estão definidos | J40: Baixa | K40: 46141
...

Sheet Plano de Testes
A1: Plano de testes | C1: (Coluna "Obs.) refere o ID# do Plano de Verificações correspondente)
A2: Equipa: Codezilla
A4: Testes Estáticos
A5: ID | B5: Módulo/Componente | C5: Descrição | D5: Dados de Input | E5: Resultado esperado | F5: Auto/Manual | G5: Sugerido por | H5: Sugerido em: | I5: Criado/Testado por: | J5: Corrido em: | K5: Resultado Obtido | L5: Obs.
A6: MS1 | B6: Model | C6: Verificar conformidade do Model com MVC | D6: Não aplicável | E6: O Model não referencia diretamente a View nem o Controller | F6: Observação | G6: AF | H6: 46141 | I6: LR | J6: 46141 | K6: Confirmado: o Model não referencia directamente a View nem o Controller. | L6: 6;43
A7: MS2 | B7: Model | C7: Inspeção de encapsulamento do estado interno | D7: Código do Model | E7: A lista de produtos não é exposta diretamente ao exterior | F7: Observação | G7: AF | H7: 46141 | I7: LR | J7: 46141 | K7: Confirmado: as listas devolvidas são cópias e não expõem directamente _listaProdutos. | L7: 43
A8: MS3 | B8: Model | C8: Verificação de correspondência com diagramas | D8: Código e diagramas | E8: Métodos e responsabilidades correspondem ao modelo definido | F8: Observação | G8: AF | H8: 46141 | I8: LR | J8: 46141 | K8: Confirmado no código actual: o Model concentra estado, lógica de negócio e persistência; falta apenas o fecho documental final com os diagramas actualizados. | L8: 43;47
A9: MS4 | B9: Model | C9: Verificação da persistência integrada | D9: Código do Model | E9: Persistência JSON ocorre apenas no Model | F9: Observação | G9: AF | H9: 46141 | I9: LR | J9: 46141 | K9: Confirmado: a persistência JSON está implementada no Model através de CarregarDados e GuardarDados. | L9: 26;27;43
A10: CS1 | B10: Controller | C10: Conformidade com MVC | D10: Não aplicável | E10: Controller coordena View e Model | F10: Observação | G10: KA | H10: 46141 | I10: LR | J10: 46141 | K10: Confirmado: o Controller coordena View e Model e medeia os fluxos principais. | L10: 3;8;45
A11: CS2 | B11: Controller | C11: Verificação de dependências | D11: Código do Controller | E11: View não comunica diretamente com Model | F11: Observação | G11: KA | H11: 46141 | I11: LR | J11: 46141 | K11: Confirmado: a View não referencia directamente o Model; a coordenação é feita pelo Controller. | L11: 13;45
A12: CS3 | B12: Controller | C12: Correspondência com diagramas | D12: Código e diagramas | E12: Fluxo MVC correto | F12: Observação | G12: KA | H12: 46141 | I12: LR | J12: 46141 | K12: Parcial: o fluxo MVC do código actual é correcto; falta confirmação documental final com os diagramas actualizados. | L12: 45;47
A13: CS4 | B13: Controller | C13: Tratamento de responsabilidades | D13: Código do Controller | E13: Controller não contém lógica de negócio | F13: Observação | G13: KA | H13: 46141 | I13: LR | J13: 46141 | K13: Confirmado: o Controller coordena, valida fluxos e trata chamadas, sem conter lógica de stock ou persistência. | L13: 8;45
A14: VS1 | B14: View | C14: Verificar conformidade da View com MVC | D14: Não aplicável | E14: A View não referencia diretamente o Model nem contém lógica de negócio | F14: Observação | G14: CB | H14: 46141 | I14: LR | J14: 46141 | K14: Confirmado: a View não referencia directamente o Model e limita-se a input/output e apresentação. | L14: 5;44
A15: VS2 | B15: View | C15: Inspeção da responsabilidade exclusiva de I/O | D15: Código da View | E15: Todos os Console.ReadLine() e Console.WriteLine() estão nas classes View, nunca no Controller ou Model | F15: Observação | G15: CB | H15: 46141 | I15: LR | J15: 46141 | K15: Confirmado: as operações de consola estão concentradas na View. | L15: 44
A16: VS3 | B16: View | C16: Verificação de correspondência com diagramas | D16: Código e diagramas | E16: Métodos e fluxos de apresentação correspondem ao diagrama de sequência definido | F16: Observação | G16: CB | H16: 46141 | I16: LR | J16: 46141 | K16: Parcial: os métodos de apresentação do código actual são coerentes; falta validação documental final com os diagramas actualizados. | L16: 44;47
